<sdf version='1.6'>
  <world name='default'>
    <model name='ground_plane'>
      <static>1</static>
      <link name='link'>
        <collision name='collision'>
          <geometry>
            <plane>
              <normal>0 0 1</normal>
              <size>100 100</size>
            </plane>
          </geometry>
          <surface>
            <friction>
              <ode>
                <mu>100</mu>
                <mu2>50</mu2>
              </ode>
              <torsional>
                <ode/>
              </torsional>
            </friction>
            <contact>
              <ode/>
            </contact>
            <bounce/>
          </surface>
          <max_contacts>10</max_contacts>
        </collision>
        <visual name='visual'>
          <cast_shadows>0</cast_shadows>
          <geometry>
            <plane>
              <normal>0 0 1</normal>
              <size>100 100</size>
            </plane>
          </geometry>
          <material>
            <script>
              <uri>file://media/materials/scripts/gazebo.material</uri>
              <name>Gazebo/Grey</name>
            </script>
          </material>
        </visual>
        <self_collide>0</self_collide>
        <kinematic>0</kinematic>
      </link>
    </model>
    <light name='sun' type='directional'>
      <cast_shadows>1</cast_shadows>
      <pose frame=''>0 0 10 0 -0 0</pose>
      <diffuse>0.8 0.8 0.8 1</diffuse>
      <specular>0.1 0.1 0.1 1</specular>
      <attenuation>
        <range>1000</range>
        <constant>0.9</constant>
        <linear>0.01</linear>
        <quadratic>0.001</quadratic>
      </attenuation>
      <direction>-0.5 0.5 -1</direction>
    </light>
    <gui fullscreen='0'>
      <camera name='user_camera'>
        <pose frame=''>7.07909 1.80569 5.29532 0 0.275643 -2.951</pose>
        <view_controller>orbit</view_controller>
        <projection_type>perspective</projection_type>
      </camera>
    </gui>
    <gravity>0 0 -9.8</gravity>
    <magnetic_field>6e-06 2.3e-05 -4.2e-05</magnetic_field>
    <atmosphere type='adiabatic'/>
    <physics name='default_physics' default='0' type='ode'>
      <max_step_size>0.001</max_step_size>
      <real_time_factor>1</real_time_factor>
      <real_time_update_rate>1000</real_time_update_rate>
    </physics>
    <scene>
      <ambient>0.4 0.4 0.4 1</ambient>
      <background>0.7 0.7 0.7 1</background>
      <shadows>1</shadows>
    </scene>
    <spherical_coordinates>
      <surface_model>EARTH_WGS84</surface_model>
      <latitude_deg>0</latitude_deg>
      <longitude_deg>0</longitude_deg>
      <elevation>0</elevation>
      <heading_deg>0</heading_deg>
    </spherical_coordinates>
    <model name='kinect_ros'>
      <static>1</static>
      <pose frame=''>-0.138 -3.25 1.978 0 0.5729 1.5</pose>
      <link name='link'>
        <inertial>
          <mass>0.1</mass>
        </inertial>
        <collision name='collision'>
          <geometry>
            <box>
              <size>0.073 0.276 0.072</size>
            </box>
          </geometry>
          <max_contacts>10</max_contacts>
          <surface>
            <contact>
              <ode/>
            </contact>
            <bounce/>
            <friction>
              <torsional>
                <ode/>
              </torsional>
              <ode/>
            </friction>
          </surface>
        </collision>
        <visual name='visual'>
          <geometry>
            <mesh>
              <uri>model://kinect/meshes/kinect.dae</uri>
            </mesh>
          </geometry>
        </visual>
        <sensor name='camera' type='depth'>
          <update_rate>20</update_rate>
          <camera name='__default__'>
            <horizontal_fov>1.0472</horizontal_fov>
            <image>
              <width>640</width>
              <height>480</height>
              <format>R8G8B8</format>
            </image>
            <clip>
              <near>0.05</near>
              <far>3</far>
            </clip>
          </camera>
          <plugin name='camera_plugin' filename='libgazebo_ros_openni_kinect.so'>
            <baseline>0.2</baseline>
            <alwaysOn>true</alwaysOn>
            <updateRate>0.0</updateRate>
            <cameraName>camera</cameraName>
            <imageTopicName>/camera/depth/image_raw</imageTopicName>
            <cameraInfoTopicName>/camera/depth/camera_info</cameraInfoTopicName>
            <depthImageTopicName>/camera/depth/image_raw</depthImageTopicName>
            <depthImageInfoTopicName>/camera/depth/camera_info</depthImageInfoTopicName>
            <pointCloudTopicName>/camera/depth/points</pointCloudTopicName>
            <frameName>camera_link</frameName>
            <pointCloudCutoff>0.05</pointCloudCutoff>
            <distortionK1>0</distortionK1>
            <distortionK2>0</distortionK2>
            <distortionK3>0</distortionK3>
            <distortionT1>0</distortionT1>
            <distortionT2>0</distortionT2>
            <CxPrime>0</CxPrime>
            <Cx>0</Cx>
            <Cy>0</Cy>
            <focalLength>0</focalLength>
            <hackBaseline>0</hackBaseline>
          </plugin>
        </sensor>
        <self_collide>0</self_collide>
        <kinematic>0</kinematic>
      </link>
    </model>
    <model name='denso'>
      <link name='BASE'>
        <pose frame=''>0 0 0 0 -0 0</pose>
        <inertial>
          <pose frame=''>0 0 0 0 -0 0</pose>
          <mass>1000</mass>
          <inertia>
            <ixx>20</ixx>
            <ixy>0</ixy>
            <ixz>0</ixz>
            <iyy>20</iyy>
            <iyz>0</iyz>
            <izz>20</izz>
          </inertia>
        </inertial>
        <collision name='BASE_collision'>
          <pose frame=''>0 0 0 0 -0 0</pose>
          <geometry>
            <mesh>
              <scale>1 1 1</scale>
              <uri>/home/aquifi/catkin_ws/src/denso/vs060/model/meshes/BASE_mesh.stl</uri>
            </mesh>
          </geometry>
          <surface>
            <contact>
              <ode/>
            </contact>
            <friction>
              <ode/>
              <torsional>
                <ode/>
              </torsional>
            </friction>
            <bounce/>
          </surface>
          <max_contacts>10</max_contacts>
        </collision>
        <visual name='BASE_visual'>
          <pose frame=''>0 0 0 0 -0 0</pose>
          <geometry>
            <mesh>
              <scale>1 1 1</scale>
              <uri>/home/aquifi/catkin_ws/src/denso/vs060/model/meshes/BASE_mesh.stl</uri>
            </mesh>
          </geometry>
          <material>
            <script>
              <name>Gazebo/Black</name>
              <uri>file://media/materials/scripts/gazebo.material</uri>
            </script>
          </material>
        </visual>
        <gravity>1</gravity>
        <velocity_decay/>
        <self_collide>0</self_collide>
        <kinematic>0</kinematic>
      </link>
      <joint name='fixed' type='revolute'>
        <child>BASE</child>
        <parent>world</parent>
        <axis>
          <limit>
            <lower>0</lower>
            <upper>0</upper>
          </limit>
          <dynamics>
            <damping>0</damping>
            <friction>0</friction>
            <spring_reference>0</spring_reference>
            <spring_stiffness>0</spring_stiffness>
          </dynamics>
          <use_parent_model_frame>1</use_parent_model_frame>
          <xyz>0 0 1</xyz>
        </axis>
      </joint>
      <link name='link_1'>
        <pose frame=''>0 0 0.182 0 -0 0</pose>
        <inertial>
          <pose frame=''>0.013885 -0.005997 0.043991 0 -0 0</pose>
          <mass>4.327</mass>
          <inertia>
            <ixx>0.025492</ixx>
            <ixy>0</ixy>
            <ixz>0</ixz>
            <iyy>0.032502</iyy>
            <iyz>-3.26672e-18</iyz>
            <izz>0.01779</izz>
          </inertia>
        </inertial>
        <collision name='link_1_collision'>
          <pose frame=''>0 0 0.182 0 -0 0</pose>
          <geometry>
            <mesh>
              <scale>1 1 1</scale>
              <uri>/home/aquifi/catkin_ws/src/denso/vs060/model/meshes/J1_mesh.stl</uri>
            </mesh>
          </geometry>
          <surface>
            <contact>
              <ode/>
            </contact>
            <friction>
              <ode/>
              <torsional>
                <ode/>
              </torsional>
            </friction>
            <bounce/>
          </surface>
          <max_contacts>10</max_contacts>
        </collision>
        <visual name='link_1_visual'>
          <pose frame=''>0 0 0.182 0 -0 0</pose>
          <geometry>
            <mesh>
              <scale>1 1 1</scale>
              <uri>/home/aquifi/catkin_ws/src/denso/vs060/model/meshes/J1_mesh.stl</uri>
            </mesh>
          </geometry>
          <material>
            <script>
              <name>Gazebo/Orange</name>
              <uri>file://media/materials/scripts/gazebo.material</uri>
            </script>
          </material>
        </visual>
        <gravity>1</gravity>
        <velocity_decay/>
        <self_collide>0</self_collide>
        <kinematic>0</kinematic>
      </link>
      <joint name='j1' type='revolute'>
        <child>link_1</child>
        <parent>BASE</parent>
        <axis>
          <xyz>0 0 1</xyz>
          <limit>
            <lower>-2.96706</lower>
            <upper>2.96706</upper>
            <effort>19.7336</effort>
            <velocity>3.2</velocity>
          </limit>
          <dynamics>
            <spring_reference>0</spring_reference>
            <spring_stiffness>0</spring_stiffness>
          </dynamics>
          <use_parent_model_frame>1</use_parent_model_frame>
        </axis>
      </joint>
      <link name='link_2'>
        <pose frame=''>0 0 0.345 0 -0 0</pose>
        <inertial>
          <pose frame=''>0.015837 -0.073696 0.010087 0 -0 0</pose>
          <mass>9.475</mass>
          <inertia>
            <ixx>0.108024</ixx>
            <ixy>0</ixy>
            <ixz>0</ixz>
            <iyy>0.025579</iyy>
            <iyz>1.93827e-17</iyz>
            <izz>0.112871</izz>
          </inertia>
        </inertial>
        <collision name='link_2_collision'>
          <pose frame=''>0 0 0.163 0 -0 0</pose>
          <geometry>
            <mesh>
              <scale>1 1 1</scale>
              <uri>/home/aquifi/catkin_ws/src/denso/vs060/model/meshes/J2_mesh.stl</uri>
            </mesh>
          </geometry>
          <surface>
            <contact>
              <ode/>
            </contact>
            <friction>
              <ode>
                <mu>0.2</mu>
                <mu2>0.2</mu2>
              </ode>
              <torsional>
                <ode/>
              </torsional>
            </friction>
            <bounce/>
          </surface>
          <max_contacts>10</max_contacts>
        </collision>
        <visual name='link_2_visual'>
          <pose frame=''>0 0 0.163 0 -0 0</pose>
          <geometry>
            <mesh>
              <scale>1 1 1</scale>
              <uri>/home/aquifi/catkin_ws/src/denso/vs060/model/meshes/J2_mesh.stl</uri>
            </mesh>
          </geometry>
          <material>
            <script>
              <name>Gazebo/Orange</name>
              <uri>file://media/materials/scripts/gazebo.material</uri>
            </script>
          </material>
        </visual>
        <gravity>1</gravity>
        <velocity_decay/>
        <self_collide>0</self_collide>
        <kinematic>0</kinematic>
      </link>
      <joint name='j2' type='revolute'>
        <child>link_2</child>
        <parent>link_1</parent>
        <axis>
          <xyz>0 1 0</xyz>
          <limit>
            <lower>-2.0944</lower>
            <upper>2.0944</upper>
            <effort>40.8447</effort>
            <velocity>3.2</velocity>
          </limit>
          <dynamics>
            <spring_reference>0</spring_reference>
            <spring_stiffness>0</spring_stiffness>
          </dynamics>
          <use_parent_model_frame>1</use_parent_model_frame>
        </axis>
      </joint>
      <link name='link_3'>
        <pose frame=''>0 0 0.65 0 -0 0</pose>
        <inertial>
          <pose frame=''>0.011544 -0.057408 0.006203 0 -0 0</pose>
          <mass>4.097</mass>
          <inertia>
            <ixx>0.015999</ixx>
            <ixy>0</ixy>
            <ixz>0</ixz>
            <iyy>0.00638</iyy>
            <iyz>2.33191e-18</iyz>
            <izz>0.016882</izz>
          </inertia>
        </inertial>
        <collision name='link_3_collision'>
          <pose frame=''>0 0 0.305 0 -0 0</pose>
          <geometry>
            <mesh>
              <scale>1 1 1</scale>
              <uri>/home/aquifi/catkin_ws/src/denso/vs060/model/meshes/J3_mesh.stl</uri>
            </mesh>
          </geometry>
          <surface>
            <contact>
              <ode/>
            </contact>
            <friction>
              <ode>
                <mu>0.2</mu>
                <mu2>0.2</mu2>
              </ode>
              <torsional>
                <ode/>
              </torsional>
            </friction>
            <bounce/>
          </surface>
          <max_contacts>10</max_contacts>
        </collision>
        <visual name='link_3_visual'>
          <pose frame=''>0 0 0.305 0 -0 0</pose>
          <geometry>
            <mesh>
              <scale>1 1 1</scale>
              <uri>/home/aquifi/catkin_ws/src/denso/vs060/model/meshes/J3_mesh.stl</uri>
            </mesh>
          </geometry>
          <material>
            <script>
              <name>Gazebo/Orange</name>
              <uri>file://media/materials/scripts/gazebo.material</uri>
            </script>
          </material>
        </visual>
        <gravity>1</gravity>
        <velocity_decay/>
        <self_collide>0</self_collide>
        <kinematic>0</kinematic>
      </link>
      <joint name='j3' type='revolute'>
        <child>link_3</child>
        <parent>link_2</parent>
        <axis>
          <xyz>0 1 0</xyz>
          <limit>
            <lower>-2.18166</lower>
            <upper>2.70526</upper>
            <effort>20.7089</effort>
            <velocity>3.2</velocity>
          </limit>
          <dynamics>
            <spring_reference>0</spring_reference>
            <spring_stiffness>0</spring_stiffness>
          </dynamics>
          <use_parent_model_frame>1</use_parent_model_frame>
        </axis>
      </joint>
      <link name='link_4'>
        <pose frame=''>-0.01 0 0.815 0 -0 0</pose>
        <inertial>
          <pose frame=''>0.003998 -0.004975 0.052919 0 -0 0</pose>
          <mass>1.779</mass>
          <inertia>
            <ixx>0.005106</ixx>
            <ixy>0</ixy>
            <ixz>0</ixz>
            <iyy>0.005266</iyy>
            <iyz>-5.87308e-19</iyz>
            <izz>0.002621</izz>
          </inertia>
        </inertial>
        <collision name='link_4_collision'>
          <pose frame=''>-0.01 0 0.165 0 -0 0</pose>
          <geometry>
            <mesh>
              <scale>1 1 1</scale>
              <uri>/home/aquifi/catkin_ws/src/denso/vs060/model/meshes/J4_mesh.stl</uri>
            </mesh>
          </geometry>
          <surface>
            <contact>
              <ode/>
            </contact>
            <friction>
              <ode>
                <mu>0.2</mu>
                <mu2>0.2</mu2>
              </ode>
              <torsional>
                <ode/>
              </torsional>
            </friction>
            <bounce/>
          </surface>
          <max_contacts>10</max_contacts>
        </collision>
        <visual name='link_4_visual'>
          <pose frame=''>-0.01 0 0.165 0 -0 0</pose>
          <geometry>
            <mesh>
              <scale>1 1 1</scale>
              <uri>/home/aquifi/catkin_ws/src/denso/vs060/model/meshes/J4_mesh.stl</uri>
            </mesh>
          </geometry>
          <material>
            <script>
              <name>Gazebo/Orange</name>
              <uri>file://media/materials/scripts/gazebo.material</uri>
            </script>
          </material>
        </visual>
        <gravity>1</gravity>
        <velocity_decay/>
        <self_collide>0</self_collide>
        <kinematic>0</kinematic>
      </link>
      <joint name='j4' type='revolute'>
        <child>link_4</child>
        <parent>link_3</parent>
        <axis>
          <xyz>0 0 1</xyz>
          <limit>
            <lower>-3.14</lower>
            <upper>3.14</upper>
            <effort>28</effort>
            <velocity>3.2</velocity>
          </limit>
          <dynamics>
            <spring_reference>0</spring_reference>
            <spring_stiffness>0</spring_stiffness>
          </dynamics>
          <use_parent_model_frame>1</use_parent_model_frame>
        </axis>
      </joint>
      <link name='link_5'>
        <pose frame=''>-0.01 0 0.95 0 -0 0</pose>
        <inertial>
          <pose frame=''>0.011902 -0.004739 0.010398 0 -0 0</pose>
          <mass>1.219</mass>
          <inertia>
            <ixx>0.111173</ixx>
            <ixy>0</ixy>
            <ixz>0</ixz>
            <iyy>0.111173</iyy>
            <iyz>0</iyz>
            <izz>0.21942</izz>
          </inertia>
        </inertial>
        <collision name='link_5_collision'>
          <pose frame=''>0 0 0.135 0 -0 0</pose>
          <geometry>
            <mesh>
              <scale>1 1 1</scale>
              <uri>/home/aquifi/catkin_ws/src/denso/vs060/model/meshes/J5_mesh.stl</uri>
            </mesh>
          </geometry>
          <surface>
            <contact>
              <ode/>
            </contact>
            <friction>
              <ode>
                <mu>0.2</mu>
                <mu2>0.2</mu2>
              </ode>
              <torsional>
                <ode/>
              </torsional>
            </friction>
            <bounce/>
          </surface>
          <max_contacts>10</max_contacts>
        </collision>
        <visual name='link_5_visual'>
          <pose frame=''>0 0 0.135 0 -0 0</pose>
          <geometry>
            <mesh>
              <scale>1 1 1</scale>
              <uri>/home/aquifi/catkin_ws/src/denso/vs060/model/meshes/J5_mesh.stl</uri>
            </mesh>
          </geometry>
          <material>
            <script>
              <name>Gazebo/Orange</name>
              <uri>file://media/materials/scripts/gazebo.material</uri>
            </script>
          </material>
        </visual>
        <gravity>1</gravity>
        <velocity_decay/>
        <self_collide>0</self_collide>
        <kinematic>0</kinematic>
      </link>
      <joint name='j5' type='revolute'>
        <child>link_5</child>
        <parent>link_4</parent>
        <axis>
          <xyz>0 1 0</xyz>
          <limit>
            <lower>-2.0944</lower>
            <upper>2.0944</upper>
            <effort>28</effort>
            <velocity>3.2</velocity>
          </limit>
          <dynamics>
            <spring_reference>0</spring_reference>
            <spring_stiffness>0</spring_stiffness>
          </dynamics>
          <use_parent_model_frame>1</use_parent_model_frame>
        </axis>
      </joint>
      <link name='Flange'>
        <pose frame=''>-0.01 0 1.02 0 -0 0</pose>
        <inertial>
          <pose frame=''>5.6e-05 0.036617 0.074006 0 -0 0</pose>
          <mass>0.365615</mass>
          <inertia>
            <ixx>0.01829</ixx>
            <ixy>4.79553e-06</ixy>
            <ixz>2.43246e-06</ixz>
            <iyy>0.0177301</iyy>
            <iyz>-0.000358864</iyz>
            <izz>0.0346753</izz>
          </inertia>
        </inertial>
        <collision name='Flange_collision'>
          <pose frame=''>0 0 0.07 0 -0 0</pose>
          <geometry>
            <mesh>
              <scale>1 1 1</scale>
              <uri>/home/aquifi/catkin_ws/src/denso/vs060/model/meshes/Flange_mesh.stl</uri>
            </mesh>
          </geometry>
          <surface>
            <contact>
              <ode/>
            </contact>
            <friction>
              <ode>
                <mu>0.2</mu>
                <mu2>0.2</mu2>
              </ode>
              <torsional>
                <ode/>
              </torsional>
            </friction>
            <bounce/>
          </surface>
          <max_contacts>10</max_contacts>
        </collision>
        <collision name='Flange_fixed_joint_lump__H1_base_link_collision_1'>
          <pose frame=''>0 0 -0.0005 0 -0 0</pose>
          <geometry>
            <mesh>
              <scale>1 1 1</scale>
              <uri>/home/aquifi/catkin_ws/src/smart_grasp_env/fh_desc/meshes/v2/palm_link_simple.dae</uri>
            </mesh>
          </geometry>
          <surface>
            <contact>
              <ode>
                <kp>1e+06</kp>
                <kd>100</kd>
                <max_vel>1</max_vel>
                <min_depth>0.002</min_depth>
              </ode>
            </contact>
            <friction>
              <ode>
                <mu>1.5</mu>
                <mu2>1.5</mu2>
                <fdir1>1 0 0</fdir1>
              </ode>
              <torsional>
                <ode/>
              </torsional>
            </friction>
            <bounce/>
          </surface>
          <max_contacts>10</max_contacts>
        </collision>
        <visual name='Flange_visual'>
          <pose frame=''>0 0 0.07 0 -0 0</pose>
          <geometry>
            <mesh>
              <scale>1 1 1</scale>
              <uri>/home/aquifi/catkin_ws/src/denso/vs060/model/meshes/Flange_mesh.stl</uri>
            </mesh>
          </geometry>
          <material>
            <script>
              <name>Gazebo/Orange</name>
              <uri>file://media/materials/scripts/gazebo.material</uri>
            </script>
          </material>
        </visual>
        <visual name='Flange_fixed_joint_lump__H1_base_link_visual_1'>
          <pose frame=''>0 0 -0.0005 0 -0 0</pose>
          <geometry>
            <mesh>
              <scale>1 1 1</scale>
              <uri>/home/aquifi/catkin_ws/src/smart_grasp_env/fh_desc/meshes/v2/palm_link_simple.dae</uri>
            </mesh>
          </geometry>
          <material>
            <script>
              <name>Gazebo/DarkGrey</name>
              <uri>file://media/materials/scripts/gazebo.material</uri>
            </script>
          </material>
        </visual>
        <visual name='Flange_fixed_joint_lump__H1_F1_palm_link_visual_2'>
          <pose frame=''>-0.045 -0.025981 -0.0005 0 -0 2.3562</pose>
          <geometry>
            <mesh>
              <scale>1 1 1</scale>
              <uri>/home/aquifi/catkin_ws/src/smart_grasp_env/fh_desc/meshes/v2/finger_palm_link.dae</uri>
            </mesh>
          </geometry>
          <material>
            <script>
              <name>Gazebo/DarkGrey</name>
              <uri>file://media/materials/scripts/gazebo.material</uri>
            </script>
          </material>
        </visual>
        <visual name='Flange_fixed_joint_lump__H1_F2_palm_link_visual_3'>
          <pose frame=''>0 0.029019 -0.0005 0 -0 0</pose>
          <geometry>
            <mesh>
              <scale>1 1 1</scale>
              <uri>/home/aquifi/catkin_ws/src/smart_grasp_env/fh_desc/meshes/v2/finger_palm_link.dae</uri>
            </mesh>
          </geometry>
          <material>
            <script>
              <name>Gazebo/DarkGrey</name>
              <uri>file://media/materials/scripts/gazebo.material</uri>
            </script>
          </material>
        </visual>
        <visual name='Flange_fixed_joint_lump__H1_F3_palm_link_visual_4'>
          <pose frame=''>0.045 -0.025981 -0.0005 0 0 -2.3562</pose>
          <geometry>
            <mesh>
              <scale>1 1 1</scale>
              <uri>/home/aquifi/catkin_ws/src/smart_grasp_env/fh_desc/meshes/v2/finger_palm_link.dae</uri>
            </mesh>
          </geometry>
          <material>
            <script>
              <name>Gazebo/DarkGrey</name>
              <uri>file://media/materials/scripts/gazebo.material</uri>
            </script>
          </material>
        </visual>
        <velocity_decay/>
        <velocity_decay/>
        <velocity_decay/>
        <velocity_decay/>
        <gravity>1</gravity>
        <velocity_decay/>
        <self_collide>0</self_collide>
        <kinematic>0</kinematic>
      </link>
      <joint name='flange' type='revolute'>
        <child>Flange</child>
        <parent>link_5</parent>
        <axis>
          <xyz>0 0 1</xyz>
          <limit>
            <lower>-6.28319</lower>
            <upper>6.28319</upper>
            <effort>28</effort>
            <velocity>3.2</velocity>
          </limit>
          <dynamics>
            <spring_reference>0</spring_reference>
            <spring_stiffness>0</spring_stiffness>
          </dynamics>
          <use_parent_model_frame>1</use_parent_model_frame>
        </axis>
      </joint>
      <link name='H1_F1_base_link'>
        <pose frame=''>-0.055 -0.025981 1.01967 0 -0 2.3786</pose>
        <inertial>
          <pose frame=''>-0.000143 0.026569 0.053875 0 -0 0</pose>
          <mass>0.174652</mass>
          <inertia>
            <ixx>0.000298373</ixx>
            <ixy>-5.05752e-07</ixy>
            <ixz>1.94983e-07</ixz>
            <iyy>0.00029963</iyy>
            <iyz>2.79565e-05</iyz>
            <izz>0.00013489</izz>
          </inertia>
        </inertial>
        <collision name='H1_F1_base_link_collision'>
          <pose frame=''>0 0 0 0 -0 0</pose>
          <geometry>
            <mesh>
              <scale>1 1 1</scale>
              <uri>/home/aquifi/catkin_ws/src/smart_grasp_env/fh_desc/meshes/v2/finger_base_link_simple.dae</uri>
            </mesh>
          </geometry>
          <surface>
            <contact>
              <ode>
                <kp>1e+06</kp>
                <kd>100</kd>
                <max_vel>1</max_vel>
                <min_depth>0.002</min_depth>
              </ode>
            </contact>
            <friction>
              <ode>
                <mu>1.5</mu>
                <mu2>1.5</mu2>
                <fdir1>1 0 0</fdir1>
              </ode>
              <torsional>
                <ode/>
              </torsional>
            </friction>
            <bounce/>
          </surface>
          <max_contacts>10</max_contacts>
        </collision>
        <visual name='H1_F1_base_link_visual'>
          <pose frame=''>0 0 0 0 -0 0</pose>
          <geometry>
            <mesh>
              <scale>1 1 1</scale>
              <uri>/home/aquifi/catkin_ws/src/smart_grasp_env/fh_desc/meshes/v2/finger_base_link_simple.dae</uri>
            </mesh>
          </geometry>
          <material>
            <script>
              <name>Gazebo/DarkGrey</name>
              <uri>file://media/materials/scripts/gazebo.material</uri>
            </script>
          </material>
        </visual>
        <gravity>1</gravity>
        <velocity_decay/>
        <self_collide>0</self_collide>
        <kinematic>0</kinematic>
      </link>
      <joint name='H1_F1J1' type='revolute'>
        <child>H1_F1_base_link</child>
        <parent>Flange</parent>
        <axis>
          <xyz>0 0 1</xyz>
          <limit>
            <lower>-0.785398</lower>
            <upper>0.785398</upper>
            <effort>50</effort>
            <velocity>1</velocity>
          </limit>
          <dynamics>
            <damping>0</damping>
            <friction>0</friction>
            <spring_reference>0</spring_reference>
            <spring_stiffness>0</spring_stiffness>
          </dynamics>
          <use_parent_model_frame>1</use_parent_model_frame>
        </axis>
        <physics>
          <ode>
            <implicit_spring_damper>1</implicit_spring_damper>
            <cfm_damping>1</cfm_damping>
            <limit>
              <cfm>0</cfm>
              <erp>0.2</erp>
            </limit>
          </ode>
        </physics>
      </joint>
      <link name='H1_F1_link_1'>
        <pose frame=''>-0.079188 -0.051278 1.1365 0.070695 -0 2.3786</pose>
        <inertial>
          <pose frame=''>-0.000142 -0.001354 0.027761 0 -0 0</pose>
          <mass>0.082776</mass>
          <inertia>
            <ixx>4.6107e-05</ixx>
            <ixy>7.47741e-08</ixy>
            <ixz>-2.25165e-07</ixz>
            <iyy>5.27678e-05</iyy>
            <iyz>-3.64603e-07</iyz>
            <izz>2.896e-05</izz>
          </inertia>
        </inertial>
        <collision name='H1_F1_link_1_collision'>
          <pose frame=''>0 0 0 0 -0 0</pose>
          <geometry>
            <mesh>
              <scale>1 1 1</scale>
              <uri>/home/aquifi/catkin_ws/src/smart_grasp_env/fh_desc/meshes/v2/finger_prox_link_simple.dae</uri>
            </mesh>
          </geometry>
          <surface>
            <contact>
              <ode>
                <kp>1e+06</kp>
                <kd>100</kd>
                <max_vel>1</max_vel>
                <min_depth>0.002</min_depth>
              </ode>
            </contact>
            <friction>
              <ode>
                <mu>1.5</mu>
                <mu2>1.5</mu2>
                <fdir1>1 0 0</fdir1>
              </ode>
              <torsional>
                <ode/>
              </torsional>
            </friction>
            <bounce/>
          </surface>
          <max_contacts>10</max_contacts>
        </collision>
        <visual name='H1_F1_link_1_visual'>
          <pose frame=''>0 0 0 0 -0 0</pose>
          <geometry>
            <mesh>
              <scale>1 1 1</scale>
              <uri>/home/aquifi/catkin_ws/src/smart_grasp_env/fh_desc/meshes/v2/finger_prox_link_simple.dae</uri>
            </mesh>
          </geometry>
          <material>
            <script>
              <name>Gazebo/DarkGrey</name>
              <uri>file://media/materials/scripts/gazebo.material</uri>
            </script>
          </material>
        </visual>
        <gravity>1</gravity>
        <velocity_decay/>
        <self_collide>0</self_collide>
        <kinematic>0</kinematic>
      </link>
      <joint name='H1_F1J2' type='revolute'>
        <child>H1_F1_link_1</child>
        <parent>H1_F1_base_link</parent>
        <axis>
          <xyz>-0.722772 0.691086 0</xyz>
          <limit>
            <lower>-1.39626</lower>
            <upper>1.0472</upper>
            <effort>50</effort>
            <velocity>1</velocity>
          </limit>
          <dynamics>
            <damping>0</damping>
            <friction>0</friction>
            <spring_reference>0</spring_reference>
            <spring_stiffness>0</spring_stiffness>
          </dynamics>
          <use_parent_model_frame>1</use_parent_model_frame>
        </axis>
        <physics>
          <ode>
            <implicit_spring_damper>1</implicit_spring_damper>
            <cfm_damping>1</cfm_damping>
            <limit>
              <cfm>0</cfm>
              <erp>0.2</erp>
            </limit>
          </ode>
        </physics>
      </joint>
      <link name='H1_F1_link_2'>
        <pose frame=''>-0.076259 -0.048215 1.19635 0.06383 -0 2.3786</pose>
        <inertial>
          <pose frame=''>0.000147 -0.001929 0.020669 0 -0 0</pose>
          <mass>0.0360682</mass>
          <inertia>
            <ixx>1.45995e-05</ixx>
            <ixy>-5.02031e-08</ixy>
            <ixz>-1.65836e-07</ixz>
            <iyy>1.46464e-05</iyy>
            <iyz>-2.25421e-07</iyz>
            <izz>4.03881e-06</izz>
          </inertia>
        </inertial>
        <collision name='H1_F1_link_2_collision'>
          <pose frame=''>0 0 0 0 -0 0</pose>
          <geometry>
            <mesh>
              <scale>1 1 1</scale>
              <uri>/home/aquifi/catkin_ws/src/smart_grasp_env/fh_desc/meshes/v2/finger_dist_link_simple.dae</uri>
            </mesh>
          </geometry>
          <surface>
            <contact>
              <ode>
                <kp>1e+06</kp>
                <kd>100</kd>
                <max_vel>1</max_vel>
                <min_depth>0.002</min_depth>
              </ode>
            </contact>
            <friction>
              <ode>
                <mu>1.5</mu>
                <mu2>1.5</mu2>
                <fdir1>1 0 0</fdir1>
              </ode>
              <torsional>
                <ode/>
              </torsional>
            </friction>
            <bounce/>
          </surface>
          <max_contacts>10</max_contacts>
        </collision>
        <collision name='H1_F1_link_2_fixed_joint_lump__H1_F1_tip_collision_1'>
          <pose frame=''>0 0 0 0 -0 0</pose>
          <geometry>
            <mesh>
              <scale>1 1 1</scale>
              <uri>/home/aquifi/catkin_ws/src/smart_grasp_env/fh_desc/meshes/omd-d18-tip.dae</uri>
            </mesh>
          </geometry>
          <surface>
            <contact>
              <ode>
                <kp>1e+06</kp>
                <kd>100</kd>
                <max_vel>1</max_vel>
                <min_depth>0.002</min_depth>
              </ode>
            </contact>
            <friction>
              <ode>
                <mu>1.5</mu>
                <mu2>1.5</mu2>
                <fdir1>1 0 0</fdir1>
              </ode>
              <torsional>
                <ode/>
              </torsional>
            </friction>
            <bounce/>
          </surface>
          <max_contacts>10</max_contacts>
        </collision>
        <visual name='H1_F1_link_2_visual'>
          <pose frame=''>0 0 0 0 -0 0</pose>
          <geometry>
            <mesh>
              <scale>1 1 1</scale>
              <uri>/home/aquifi/catkin_ws/src/smart_grasp_env/fh_desc/meshes/v2/finger_dist_link_simple.dae</uri>
            </mesh>
          </geometry>
          <material>
            <script>
              <name>Gazebo/DarkGrey</name>
              <uri>file://media/materials/scripts/gazebo.material</uri>
            </script>
          </material>
        </visual>
        <visual name='H1_F1_link_2_fixed_joint_lump__H1_F1_tip_visual_1'>
          <pose frame=''>0 0 0 0 -0 0</pose>
          <geometry>
            <mesh>
              <scale>1 1 1</scale>
              <uri>/home/aquifi/catkin_ws/src/smart_grasp_env/fh_desc/meshes/omd-d18-tip.dae</uri>
            </mesh>
          </geometry>
          <material>
            <script>
              <name>Gazebo/DarkGrey</name>
              <uri>file://media/materials/scripts/gazebo.material</uri>
            </script>
          </material>
        </visual>
        <velocity_decay/>
        <gravity>1</gravity>
        <velocity_decay/>
        <self_collide>0</self_collide>
        <kinematic>0</kinematic>
      </link>
      <joint name='H1_F1J3' type='revolute'>
        <child>H1_F1_link_2</child>
        <parent>H1_F1_link_1</parent>
        <axis>
          <xyz>-0.722772 0.691086 0</xyz>
          <limit>
            <lower>-1.0472</lower>
            <upper>1.5708</upper>
            <effort>50</effort>
            <velocity>1</velocity>
          </limit>
          <dynamics>
            <damping>0</damping>
            <friction>0</friction>
            <spring_reference>0</spring_reference>
            <spring_stiffness>0</spring_stiffness>
          </dynamics>
          <use_parent_model_frame>1</use_parent_model_frame>
        </axis>
        <physics>
          <ode>
            <implicit_spring_damper>1</implicit_spring_damper>
            <cfm_damping>1</cfm_damping>
            <limit>
              <cfm>0</cfm>
              <erp>0.2</erp>
            </limit>
          </ode>
        </physics>
      </joint>
      <link name='H1_F2_base_link'>
        <pose frame=''>-0.01 0.029019 1.01967 0 -0 0.022402</pose>
        <inertial>
          <pose frame=''>-0.000143 0.026569 0.053875 0 -0 0</pose>
          <mass>0.174652</mass>
          <inertia>
            <ixx>0.000298373</ixx>
            <ixy>-5.05752e-07</ixy>
            <ixz>1.94983e-07</ixz>
            <iyy>0.00029963</iyy>
            <iyz>2.79565e-05</iyz>
            <izz>0.00013489</izz>
          </inertia>
        </inertial>
        <collision name='H1_F2_base_link_collision'>
          <pose frame=''>0 0 0 0 -0 0</pose>
          <geometry>
            <mesh>
              <scale>1 1 1</scale>
              <uri>/home/aquifi/catkin_ws/src/smart_grasp_env/fh_desc/meshes/v2/finger_base_link_simple.dae</uri>
            </mesh>
          </geometry>
          <surface>
            <contact>
              <ode>
                <kp>1e+06</kp>
                <kd>100</kd>
                <max_vel>1</max_vel>
                <min_depth>0.002</min_depth>
              </ode>
            </contact>
            <friction>
              <ode>
                <mu>1.5</mu>
                <mu2>1.5</mu2>
                <fdir1>1 0 0</fdir1>
              </ode>
              <torsional>
                <ode/>
              </torsional>
            </friction>
            <bounce/>
          </surface>
          <max_contacts>10</max_contacts>
        </collision>
        <visual name='H1_F2_base_link_visual'>
          <pose frame=''>0 0 0 0 -0 0</pose>
          <geometry>
            <mesh>
              <scale>1 1 1</scale>
              <uri>/home/aquifi/catkin_ws/src/smart_grasp_env/fh_desc/meshes/v2/finger_base_link_simple.dae</uri>
            </mesh>
          </geometry>
          <material>
            <script>
              <name>Gazebo/DarkGrey</name>
              <uri>file://media/materials/scripts/gazebo.material</uri>
            </script>
          </material>
        </visual>
        <gravity>1</gravity>
        <velocity_decay/>
        <self_collide>0</self_collide>
        <kinematic>0</kinematic>
      </link>
      <joint name='H1_F2J1' type='revolute'>
        <child>H1_F2_base_link</child>
        <parent>Flange</parent>
        <axis>
          <xyz>0 0 1</xyz>
          <limit>
            <lower>-0.785398</lower>
            <upper>0.785398</upper>
            <effort>30</effort>
            <velocity>1</velocity>
          </limit>
          <dynamics>
            <damping>0</damping>
            <friction>0</friction>
            <spring_reference>0</spring_reference>
            <spring_stiffness>0</spring_stiffness>
          </dynamics>
          <use_parent_model_frame>1</use_parent_model_frame>
        </axis>
        <physics>
          <ode>
            <implicit_spring_damper>1</implicit_spring_damper>
            <cfm_damping>1</cfm_damping>
            <limit>
              <cfm>0</cfm>
              <erp>0.2</erp>
            </limit>
          </ode>
        </physics>
      </joint>
      <link name='H1_F2_link_1'>
        <pose frame=''>-0.010784 0.06401 1.1365 0.070695 0 0.022402</pose>
        <inertial>
          <pose frame=''>-0.000142 -0.001354 0.027761 0 -0 0</pose>
          <mass>0.082776</mass>
          <inertia>
            <ixx>4.6107e-05</ixx>
            <ixy>7.47741e-08</ixy>
            <ixz>-2.25165e-07</ixz>
            <iyy>5.27678e-05</iyy>
            <iyz>-3.64603e-07</iyz>
            <izz>2.896e-05</izz>
          </inertia>
        </inertial>
        <collision name='H1_F2_link_1_collision'>
          <pose frame=''>0 0 0 0 -0 0</pose>
          <geometry>
            <mesh>
              <scale>1 1 1</scale>
              <uri>/home/aquifi/catkin_ws/src/smart_grasp_env/fh_desc/meshes/v2/finger_prox_link_simple.dae</uri>
            </mesh>
          </geometry>
          <surface>
            <contact>
              <ode>
                <kp>1e+06</kp>
                <kd>100</kd>
                <max_vel>1</max_vel>
                <min_depth>0.002</min_depth>
              </ode>
            </contact>
            <friction>
              <ode>
                <mu>1.5</mu>
                <mu2>1.5</mu2>
                <fdir1>1 0 0</fdir1>
              </ode>
              <torsional>
                <ode/>
              </torsional>
            </friction>
            <bounce/>
          </surface>
          <max_contacts>10</max_contacts>
        </collision>
        <visual name='H1_F2_link_1_visual'>
          <pose frame=''>0 0 0 0 -0 0</pose>
          <geometry>
            <mesh>
              <scale>1 1 1</scale>
              <uri>/home/aquifi/catkin_ws/src/smart_grasp_env/fh_desc/meshes/v2/finger_prox_link_simple.dae</uri>
            </mesh>
          </geometry>
          <material>
            <script>
              <name>Gazebo/DarkGrey</name>
              <uri>file://media/materials/scripts/gazebo.material</uri>
            </script>
          </material>
        </visual>
        <gravity>1</gravity>
        <velocity_decay/>
        <self_collide>0</self_collide>
        <kinematic>0</kinematic>
      </link>
      <joint name='H1_F2J2' type='revolute'>
        <child>H1_F2_link_1</child>
        <parent>H1_F2_base_link</parent>
        <axis>
          <xyz>0.999749 0.0224 0</xyz>
          <limit>
            <lower>-1.39626</lower>
            <upper>1.0472</upper>
            <effort>30</effort>
            <velocity>1</velocity>
          </limit>
          <dynamics>
            <damping>0</damping>
            <friction>0</friction>
            <spring_reference>0</spring_reference>
            <spring_stiffness>0</spring_stiffness>
          </dynamics>
          <use_parent_model_frame>1</use_parent_model_frame>
        </axis>
        <physics>
          <ode>
            <implicit_spring_damper>1</implicit_spring_damper>
            <cfm_damping>1</cfm_damping>
            <limit>
              <cfm>0</cfm>
              <erp>0.2</erp>
            </limit>
          </ode>
        </physics>
      </joint>
      <link name='H1_F2_link_2'>
        <pose frame=''>-0.010689 0.059773 1.19635 0.06383 -0 0.022402</pose>
        <inertial>
          <pose frame=''>0.000147 -0.001929 0.020669 0 -0 0</pose>
          <mass>0.0360682</mass>
          <inertia>
            <ixx>1.45995e-05</ixx>
            <ixy>-5.02031e-08</ixy>
            <ixz>-1.65836e-07</ixz>
            <iyy>1.46464e-05</iyy>
            <iyz>-2.25421e-07</iyz>
            <izz>4.03881e-06</izz>
          </inertia>
        </inertial>
        <collision name='H1_F2_link_2_collision'>
          <pose frame=''>0 0 0 0 -0 0</pose>
          <geometry>
            <mesh>
              <scale>1 1 1</scale>
              <uri>/home/aquifi/catkin_ws/src/smart_grasp_env/fh_desc/meshes/v2/finger_dist_link_simple.dae</uri>
            </mesh>
          </geometry>
          <surface>
            <contact>
              <ode>
                <kp>1e+06</kp>
                <kd>100</kd>
                <max_vel>1</max_vel>
                <min_depth>0.002</min_depth>
              </ode>
            </contact>
            <friction>
              <ode>
                <mu>1.5</mu>
                <mu2>1.5</mu2>
                <fdir1>1 0 0</fdir1>
              </ode>
              <torsional>
                <ode/>
              </torsional>
            </friction>
            <bounce/>
          </surface>
          <max_contacts>10</max_contacts>
        </collision>
        <collision name='H1_F2_link_2_fixed_joint_lump__H1_F2_tip_collision_1'>
          <pose frame=''>0 0 0 0 -0 0</pose>
          <geometry>
            <mesh>
              <scale>1 1 1</scale>
              <uri>/home/aquifi/catkin_ws/src/smart_grasp_env/fh_desc/meshes/omd-d18-tip.dae</uri>
            </mesh>
          </geometry>
          <surface>
            <contact>
              <ode>
                <kp>1e+06</kp>
                <kd>100</kd>
                <max_vel>1</max_vel>
                <min_depth>0.002</min_depth>
              </ode>
            </contact>
            <friction>
              <ode>
                <mu>1.5</mu>
                <mu2>1.5</mu2>
                <fdir1>1 0 0</fdir1>
              </ode>
              <torsional>
                <ode/>
              </torsional>
            </friction>
            <bounce/>
          </surface>
          <max_contacts>10</max_contacts>
        </collision>
        <visual name='H1_F2_link_2_visual'>
          <pose frame=''>0 0 0 0 -0 0</pose>
          <geometry>
            <mesh>
              <scale>1 1 1</scale>
              <uri>/home/aquifi/catkin_ws/src/smart_grasp_env/fh_desc/meshes/v2/finger_dist_link_simple.dae</uri>
            </mesh>
          </geometry>
          <material>
            <script>
              <name>Gazebo/DarkGrey</name>
              <uri>file://media/materials/scripts/gazebo.material</uri>
            </script>
          </material>
        </visual>
        <visual name='H1_F2_link_2_fixed_joint_lump__H1_F2_tip_visual_1'>
          <pose frame=''>0 0 0 0 -0 0</pose>
          <geometry>
            <mesh>
              <scale>1 1 1</scale>
              <uri>/home/aquifi/catkin_ws/src/smart_grasp_env/fh_desc/meshes/omd-d18-tip.dae</uri>
            </mesh>
          </geometry>
          <material>
            <script>
              <name>Gazebo/DarkGrey</name>
              <uri>file://media/materials/scripts/gazebo.material</uri>
            </script>
          </material>
        </visual>
        <velocity_decay/>
        <gravity>1</gravity>
        <velocity_decay/>
        <self_collide>0</self_collide>
        <kinematic>0</kinematic>
      </link>
      <joint name='H1_F2J3' type='revolute'>
        <child>H1_F2_link_2</child>
        <parent>H1_F2_link_1</parent>
        <axis>
          <xyz>0.999749 0.0224 0</xyz>
          <limit>
            <lower>-1.0472</lower>
            <upper>1.5708</upper>
            <effort>30</effort>
            <velocity>1</velocity>
          </limit>
          <dynamics>
            <damping>0</damping>
            <friction>0</friction>
            <spring_reference>0</spring_reference>
            <spring_stiffness>0</spring_stiffness>
          </dynamics>
          <use_parent_model_frame>1</use_parent_model_frame>
        </axis>
        <physics>
          <ode>
            <implicit_spring_damper>1</implicit_spring_damper>
            <cfm_damping>1</cfm_damping>
            <limit>
              <cfm>0</cfm>
              <erp>0.2</erp>
            </limit>
          </ode>
        </physics>
      </joint>
      <link name='H1_F3_base_link'>
        <pose frame=''>0.035 -0.025981 1.01967 -0 -0 -2.3338</pose>
        <inertial>
          <pose frame=''>-0.000143 0.026569 0.053875 0 -0 0</pose>
          <mass>0.174652</mass>
          <inertia>
            <ixx>0.000298373</ixx>
            <ixy>-5.05752e-07</ixy>
            <ixz>1.94983e-07</ixz>
            <iyy>0.00029963</iyy>
            <iyz>2.79565e-05</iyz>
            <izz>0.00013489</izz>
          </inertia>
        </inertial>
        <collision name='H1_F3_base_link_collision'>
          <pose frame=''>0 0 0 0 -0 0</pose>
          <geometry>
            <mesh>
              <scale>1 1 1</scale>
              <uri>/home/aquifi/catkin_ws/src/smart_grasp_env/fh_desc/meshes/v2/finger_base_link_simple.dae</uri>
            </mesh>
          </geometry>
          <surface>
            <contact>
              <ode>
                <kp>1e+06</kp>
                <kd>100</kd>
                <max_vel>1</max_vel>
                <min_depth>0.002</min_depth>
              </ode>
            </contact>
            <friction>
              <ode>
                <mu>1.5</mu>
                <mu2>1.5</mu2>
                <fdir1>1 0 0</fdir1>
              </ode>
              <torsional>
                <ode/>
              </torsional>
            </friction>
            <bounce/>
          </surface>
          <max_contacts>10</max_contacts>
        </collision>
        <visual name='H1_F3_base_link_visual'>
          <pose frame=''>0 0 0 0 -0 0</pose>
          <geometry>
            <mesh>
              <scale>1 1 1</scale>
              <uri>/home/aquifi/catkin_ws/src/smart_grasp_env/fh_desc/meshes/v2/finger_base_link_simple.dae</uri>
            </mesh>
          </geometry>
          <material>
            <script>
              <name>Gazebo/DarkGrey</name>
              <uri>file://media/materials/scripts/gazebo.material</uri>
            </script>
          </material>
        </visual>
        <gravity>1</gravity>
        <velocity_decay/>
        <self_collide>0</self_collide>
        <kinematic>0</kinematic>
      </link>
      <joint name='H1_F3J1' type='revolute'>
        <child>H1_F3_base_link</child>
        <parent>Flange</parent>
        <axis>
          <xyz>0 0 1</xyz>
          <limit>
            <lower>-0.785398</lower>
            <upper>0.785398</upper>
            <effort>30</effort>
            <velocity>1</velocity>
          </limit>
          <dynamics>
            <damping>0</damping>
            <friction>0</friction>
            <spring_reference>0</spring_reference>
            <spring_stiffness>0</spring_stiffness>
          </dynamics>
          <use_parent_model_frame>1</use_parent_model_frame>
        </axis>
        <physics>
          <ode>
            <implicit_spring_damper>1</implicit_spring_damper>
            <cfm_damping>1</cfm_damping>
            <limit>
              <cfm>0</cfm>
              <erp>0.2</erp>
            </limit>
          </ode>
        </physics>
      </joint>
      <link name='H1_F3_link_1'>
        <pose frame=''>0.060297 -0.050169 1.1365 0.070695 -0 -2.3338</pose>
        <inertial>
          <pose frame=''>-0.000142 -0.001354 0.027761 0 -0 0</pose>
          <mass>0.082776</mass>
          <inertia>
            <ixx>4.6107e-05</ixx>
            <ixy>7.47741e-08</ixy>
            <ixz>-2.25165e-07</ixz>
            <iyy>5.27678e-05</iyy>
            <iyz>-3.64603e-07</iyz>
            <izz>2.896e-05</izz>
          </inertia>
        </inertial>
        <collision name='H1_F3_link_1_collision'>
          <pose frame=''>0 0 0 0 -0 0</pose>
          <geometry>
            <mesh>
              <scale>1 1 1</scale>
              <uri>/home/aquifi/catkin_ws/src/smart_grasp_env/fh_desc/meshes/v2/finger_prox_link_simple.dae</uri>
            </mesh>
          </geometry>
          <surface>
            <contact>
              <ode>
                <kp>1e+06</kp>
                <kd>100</kd>
                <max_vel>1</max_vel>
                <min_depth>0.002</min_depth>
              </ode>
            </contact>
            <friction>
              <ode>
                <mu>1.5</mu>
                <mu2>1.5</mu2>
                <fdir1>1 0 0</fdir1>
              </ode>
              <torsional>
                <ode/>
              </torsional>
            </friction>
            <bounce/>
          </surface>
          <max_contacts>10</max_contacts>
        </collision>
        <visual name='H1_F3_link_1_visual'>
          <pose frame=''>0 0 0 0 -0 0</pose>
          <geometry>
            <mesh>
              <scale>1 1 1</scale>
              <uri>/home/aquifi/catkin_ws/src/smart_grasp_env/fh_desc/meshes/v2/finger_prox_link_simple.dae</uri>
            </mesh>
          </geometry>
          <material>
            <script>
              <name>Gazebo/DarkGrey</name>
              <uri>file://media/materials/scripts/gazebo.material</uri>
            </script>
          </material>
        </visual>
        <gravity>1</gravity>
        <velocity_decay/>
        <self_collide>0</self_collide>
        <kinematic>0</kinematic>
      </link>
      <joint name='H1_F3J2' type='revolute'>
        <child>H1_F3_link_1</child>
        <parent>H1_F3_base_link</parent>
        <axis>
          <xyz>-0.691094 -0.722765 0</xyz>
          <limit>
            <lower>-1.39626</lower>
            <upper>1.0472</upper>
            <effort>30</effort>
            <velocity>1</velocity>
          </limit>
          <dynamics>
            <damping>0</damping>
            <friction>0</friction>
            <spring_reference>0</spring_reference>
            <spring_stiffness>0</spring_stiffness>
          </dynamics>
          <use_parent_model_frame>1</use_parent_model_frame>
        </axis>
        <physics>
          <ode>
            <implicit_spring_damper>1</implicit_spring_damper>
            <cfm_damping>1</cfm_damping>
            <limit>
              <cfm>0</cfm>
              <erp>0.2</erp>
            </limit>
          </ode>
        </physics>
      </joint>
      <link name='H1_F3_link_2'>
        <pose frame=''>0.057234 -0.04724 1.19635 0.06383 0 -2.3338</pose>
        <inertial>
          <pose frame=''>0.000147 -0.001929 0.020669 0 -0 0</pose>
          <mass>0.0360682</mass>
          <inertia>
            <ixx>1.45995e-05</ixx>
            <ixy>-5.02031e-08</ixy>
            <ixz>-1.65836e-07</ixz>
            <iyy>1.46464e-05</iyy>
            <iyz>-2.25421e-07</iyz>
            <izz>4.03881e-06</izz>
          </inertia>
        </inertial>
        <collision name='H1_F3_link_2_collision'>
          <pose frame=''>0 0 0 0 -0 0</pose>
          <geometry>
            <mesh>
              <scale>1 1 1</scale>
              <uri>/home/aquifi/catkin_ws/src/smart_grasp_env/fh_desc/meshes/v2/finger_dist_link_simple.dae</uri>
            </mesh>
          </geometry>
          <surface>
            <contact>
              <ode>
                <kp>1e+06</kp>
                <kd>100</kd>
                <max_vel>1</max_vel>
                <min_depth>0.002</min_depth>
              </ode>
            </contact>
            <friction>
              <ode>
                <mu>1.5</mu>
                <mu2>1.5</mu2>
                <fdir1>1 0 0</fdir1>
              </ode>
              <torsional>
                <ode/>
              </torsional>
            </friction>
            <bounce/>
          </surface>
          <max_contacts>10</max_contacts>
        </collision>
        <collision name='H1_F3_link_2_fixed_joint_lump__H1_F3_tip_collision_1'>
          <pose frame=''>0 0 0 0 -0 0</pose>
          <geometry>
            <mesh>
              <scale>1 1 1</scale>
              <uri>/home/aquifi/catkin_ws/src/smart_grasp_env/fh_desc/meshes/omd-d18-tip.dae</uri>
            </mesh>
          </geometry>
          <surface>
            <contact>
              <ode>
                <kp>1e+06</kp>
                <kd>100</kd>
                <max_vel>1</max_vel>
                <min_depth>0.002</min_depth>
              </ode>
            </contact>
            <friction>
              <ode>
                <mu>1.5</mu>
                <mu2>1.5</mu2>
                <fdir1>1 0 0</fdir1>
              </ode>
              <torsional>
                <ode/>
              </torsional>
            </friction>
            <bounce/>
          </surface>
          <max_contacts>10</max_contacts>
        </collision>
        <visual name='H1_F3_link_2_visual'>
          <pose frame=''>0 0 0 0 -0 0</pose>
          <geometry>
            <mesh>
              <scale>1 1 1</scale>
              <uri>/home/aquifi/catkin_ws/src/smart_grasp_env/fh_desc/meshes/v2/finger_dist_link_simple.dae</uri>
            </mesh>
          </geometry>
          <material>
            <script>
              <name>Gazebo/DarkGrey</name>
              <uri>file://media/materials/scripts/gazebo.material</uri>
            </script>
          </material>
        </visual>
        <visual name='H1_F3_link_2_fixed_joint_lump__H1_F3_tip_visual_1'>
          <pose frame=''>0 0 0 0 -0 0</pose>
          <geometry>
            <mesh>
              <scale>1 1 1</scale>
              <uri>/home/aquifi/catkin_ws/src/smart_grasp_env/fh_desc/meshes/omd-d18-tip.dae</uri>
            </mesh>
          </geometry>
          <material>
            <script>
              <name>Gazebo/DarkGrey</name>
              <uri>file://media/materials/scripts/gazebo.material</uri>
            </script>
          </material>
        </visual>
        <velocity_decay/>
        <gravity>1</gravity>
        <velocity_decay/>
        <self_collide>0</self_collide>
        <kinematic>0</kinematic>
      </link>
      <joint name='H1_F3J3' type='revolute'>
        <child>H1_F3_link_2</child>
        <parent>H1_F3_link_1</parent>
        <axis>
          <xyz>-0.691094 -0.722765 0</xyz>
          <limit>
            <lower>-1.0472</lower>
            <upper>1.5708</upper>
            <effort>30</effort>
            <velocity>1</velocity>
          </limit>
          <dynamics>
            <damping>0</damping>
            <friction>0</friction>
            <spring_reference>0</spring_reference>
            <spring_stiffness>0</spring_stiffness>
          </dynamics>
          <use_parent_model_frame>1</use_parent_model_frame>
        </axis>
        <physics>
          <ode>
            <implicit_spring_damper>1</implicit_spring_damper>
            <cfm_damping>1</cfm_damping>
            <limit>
              <cfm>0</cfm>
              <erp>0.2</erp>
            </limit>
          </ode>
        </physics>
      </joint>
      <static>0</static>
      <plugin name='gazebo_ros_control' filename='libgazebo_ros_control.so'>
        <robotNamespace>/vs060</robotNamespace>
        <robotSimType>gazebo_ros_control/DefaultRobotHWSim</robotSimType>
      </plugin>
      <pose frame=''>0 0 0 0 -0 0</pose>
    </model>
    <model name='coke_can'>
      <link name='link'>
        <inertial>
          <pose frame=''>-0.01 -0.012 0.15 0 -0 0</pose>
          <mass>0.39</mass>
          <inertia>
            <ixx>0.00058</ixx>
            <ixy>0</ixy>
            <ixz>0</ixz>
            <iyy>0.00058</iyy>
            <iyz>0</iyz>
            <izz>0.00019</izz>
          </inertia>
        </inertial>
        <collision name='collision'>
          <pose frame=''>0 0 -0.46 0 -0 0</pose>
          <geometry>
            <mesh>
              <uri>model://coke_can/meshes/coke_can.dae</uri>
            </mesh>
          </geometry>
          <surface>
            <friction>
              <ode>
                <mu>1</mu>
                <mu2>1</mu2>
              </ode>
              <torsional>
                <ode/>
              </torsional>
            </friction>
            <contact>
              <ode>
                <kp>1e+07</kp>
                <kd>1</kd>
                <min_depth>0.001</min_depth>
                <max_vel>0.1</max_vel>
              </ode>
            </contact>
            <bounce/>
          </surface>
          <max_contacts>10</max_contacts>
        </collision>
        <visual name='visual'>
          <pose frame=''>0 0 -0.46 0 -0 0</pose>
          <geometry>
            <mesh>
              <uri>model://coke_can/meshes/coke_can.dae</uri>
            </mesh>
          </geometry>
        </visual>
        <self_collide>0</self_collide>
        <kinematic>0</kinematic>
      </link>
      <pose frame=''>0 -0.5 0 0 -0 0</pose>
    </model>
    <state world_name='default'>
      <sim_time>91 828000000</sim_time>
      <real_time>94 176532075</real_time>
      <wall_time>1533081234 389541267</wall_time>
      <iterations>91828</iterations>
      <model name='coke_can'>
        <pose frame=''>-1.3e-05 -0.500056 -0.003988 -0.01578 0.003494 0.000221</pose>
        <scale>1 1 1</scale>
        <link name='link'>
          <pose frame=''>-1.3e-05 -0.500056 -0.003988 -0.01578 0.003494 0.000221</pose>
          <velocity>0 0 0 0 -0 0</velocity>
          <acceleration>-0.452787 0.161724 -0.089413 2.0163 -0.028112 2.59238</acceleration>
          <wrench>-0.176587 0.063072 -0.034871 0 -0 0</wrench>
        </link>
      </model>
      <model name='denso'>
        <pose frame=''>0 0 0 0 -0 0</pose>
        <scale>1 1 1</scale>
        <link name='BASE'>
          <pose frame=''>0 0 0 0 -0 0</pose>
          <velocity>0 0 0 0 -0 0</velocity>
          <acceleration>1.2e-05 -1.2e-05 -0.000158 -0.000703 0.000465 0.000295</acceleration>
          <wrench>0.011945 -0.012151 -0.157787 0 -0 0</wrench>
        </link>
        <link name='Flange'>
          <pose frame=''>-0.010002 -2e-06 1.02 -0 -4e-06 -4.4e-05</pose>
          <velocity>-0.000273 3e-06 -5e-06 1e-06 -0.00086 0.000125</velocity>
          <acceleration>-0.341598 0.002886 -0.004438 0.001138 -0.860479 0.12534</acceleration>
          <wrench>-0.124893 0.001055 -0.001623 0 -0 0</wrench>
        </link>
        <link name='H1_F1_base_link'>
          <pose frame=''>-0.055003 -0.02598 1.01967 -2e-06 4e-06 2.37856</pose>
          <velocity>-0.00027 -3e-06 -4.4e-05 4e-06 -0.000864 9.5e-05</velocity>
          <acceleration>-0.314952 -0.004753 -0.05948 -0.007138 -0.869963 -0.214503</acceleration>
          <wrench>-0.055007 -0.00083 -0.010388 0 -0 0</wrench>
        </link>
        <link name='H1_F1_link_1'>
          <pose frame=''>-0.079193 -0.051276 1.1365 0.070693 4e-06 2.37856</pose>
          <velocity>-0.000369 -6e-06 -6.5e-05 -4.1e-05 -0.000822 9.5e-05</velocity>
          <acceleration>-0.391693 -0.004185 -0.06269 0.019567 -0.877509 0.072746</acceleration>
          <wrench>-0.032423 -0.000346 -0.005189 0 -0 0</wrench>
        </link>
        <link name='H1_F1_link_2'>
          <pose frame=''>-0.076264 -0.048213 1.19635 0.063828 4e-06 2.37856</pose>
          <velocity>-0.000418 -3e-06 -6.2e-05 2e-06 -0.000862 9.5e-05</velocity>
          <acceleration>-0.436173 -0.002621 -0.060374 0.004942 -0.861595 0.04876</acceleration>
          <wrench>-0.015732 -9.5e-05 -0.002178 0 -0 0</wrench>
        </link>
        <link name='H1_F2_base_link'>
          <pose frame=''>-0.010001 0.029017 1.01967 -1e-06 -4e-06 0.022364</pose>
          <velocity>-0.000277 3e-06 -4e-06 4e-06 -0.000864 0.000117</velocity>
          <acceleration>-0.326768 0.002486 -0.00495 0.003991 -0.8641 0.11655</acceleration>
          <wrench>-0.057071 0.000434 -0.000865 0 -0 0</wrench>
        </link>
        <link name='H1_F2_link_1'>
          <pose frame=''>-0.010784 0.064009 1.1365 0.070693 -4e-06 0.022364</pose>
          <velocity>-0.000382 2e-06 -5e-06 -9.4e-05 -0.000868 0.000117</velocity>
          <acceleration>-0.405704 0.004819 -0.004743 -0.096313 -0.874412 0.166645</acceleration>
          <wrench>-0.033583 0.000399 -0.000393 0 -0 0</wrench>
        </link>
        <link name='H1_F2_link_2'>
          <pose frame=''>-0.01069 0.059772 1.19635 0.063829 -4e-06 0.022365</pose>
          <velocity>-0.000434 8e-06 -5e-06 7e-06 -0.000864 0.000118</velocity>
          <acceleration>-0.450916 0.007768 -0.004367 0.009793 -0.87434 0.261869</acceleration>
          <wrench>-0.016264 0.00028 -0.000158 0 -0 0</wrench>
        </link>
        <link name='H1_F3_base_link'>
          <pose frame=''>0.034997 -0.025984 1.01967 2e-06 2e-06 -2.33384</pose>
          <velocity>-0.00027 8e-06 3.4e-05 0 -0.000859 0.000144</velocity>
          <acceleration>-0.313982 0.010991 0.050823 0.010442 -0.858796 -0.159485</acceleration>
          <wrench>-0.054838 0.00192 0.008876 0 -0 0</wrench>
        </link>
        <link name='H1_F3_link_1'>
          <pose frame=''>0.060292 -0.050173 1.1365 0.070696 2e-06 -2.33384</pose>
          <velocity>-0.000368 1.2e-05 5.6e-05 -8.9e-05 -0.000955 0.000141</velocity>
          <acceleration>-0.394487 0.013628 0.053564 -0.156509 -1.03111 0.133011</acceleration>
          <wrench>-0.032654 0.001128 0.004434 0 -0 0</wrench>
        </link>
        <link name='H1_F3_link_2'>
          <pose frame=''>0.057229 -0.047244 1.19635 0.063833 2e-06 -2.33384</pose>
          <velocity>-0.000426 1.6e-05 5.3e-05 -0.000293 -0.001175 0.00014</velocity>
          <acceleration>-0.450159 0.021796 0.049271 -0.296046 -1.18 0.194299</acceleration>
          <wrench>-0.016236 0.000786 0.001777 0 -0 0</wrench>
        </link>
        <link name='link_1'>
          <pose frame=''>0 0 0.182 -1e-06 1e-06 6e-06</pose>
          <velocity>0 0 0 1e-06 -1e-06 2.1e-05</velocity>
          <acceleration>0.000305 0.000555 -7e-05 0.001316 -0.001073 0.020513</acceleration>
          <wrench>0.001319 0.0024 -0.000301 0 -0 0</wrench>
        </link>
        <link name='link_2'>
          <pose frame=''>0 0 0.345 2e-06 -0 6e-06</pose>
          <velocity>0 0 0 -3e-06 -0.000257 2.2e-05</velocity>
          <acceleration>-0.000604 0.000789 0.004263 -0.003458 -0.256523 0.021658</acceleration>
          <wrench>-0.005726 0.00748 0.040388 0 -0 0</wrench>
        </link>
        <link name='link_3'>
          <pose frame=''>0 -1e-06 0.65 2e-06 -1e-06 6e-06</pose>
          <velocity>-7.7e-05 2e-06 0 -5e-06 -0.000453 2.1e-05</velocity>
          <acceleration>-0.078244 0.002003 0.005489 -0.0046 -0.452646 0.02118</acceleration>
          <wrench>-0.320566 0.008206 0.022489 0 -0 0</wrench>
        </link>
        <link name='link_4'>
          <pose frame=''>-0.010001 -1e-06 0.815 3e-06 -4e-06 -4.4e-05</pose>
          <velocity>-0.000152 2e-06 -5e-06 -6e-06 -0.000456 0.000126</velocity>
          <acceleration>-0.175119 0.002918 -0.00267 -0.006156 -0.455631 0.125923</acceleration>
          <wrench>-0.311537 0.005192 -0.004751 0 -0 0</wrench>
        </link>
        <link name='link_5'>
          <pose frame=''>-0.010002 -2e-06 0.95 0 -4e-06 -4.5e-05</pose>
          <velocity>-0.000213 3e-06 -5e-06 1e-06 -0.00086 0.000128</velocity>
          <acceleration>-0.221404 0.004551 0.005691 0.00085 -0.85996 0.127776</acceleration>
          <wrench>-0.269891 0.005547 0.006937 0 -0 0</wrench>
        </link>
      </model>
      <model name='ground_plane'>
        <pose frame=''>0 0 0 0 -0 0</pose>
        <scale>1 1 1</scale>
        <link name='link'>
          <pose frame=''>0 0 0 0 -0 0</pose>
          <velocity>0 0 0 0 -0 0</velocity>
          <acceleration>0 0 0 0 -0 0</acceleration>
          <wrench>0 0 0 0 -0 0</wrench>
        </link>
      </model>
      <model name='kinect_ros'>
        <pose frame=''>-0.138 -3.25 1.978 0 0.5729 1.5</pose>
        <scale>1 1 1</scale>
        <link name='link'>
          <pose frame=''>-0.138 -3.25 1.978 0 0.5729 1.5</pose>
          <velocity>0 0 0 0 -0 0</velocity>
          <acceleration>0 0 0 0 -0 0</acceleration>
          <wrench>0 0 0 0 -0 0</wrench>
        </link>
      </model>
      <light name='sun'>
        <pose frame=''>0 0 10 0 -0 0</pose>
      </light>
    </state>
  </world>
</sdf>
